Workbook

Sheet 00_README
A1: BARMM HEALTH SYSTEMS DIAGNOSTICS — CONSOLIDATED RAW DATA AND METADATA
A4: WHAT IS FACT, WHAT IS DERIVED
A5: Black text, no fill | B5: Value transcribed verbatim from the source document. This is the report as printed.
A6: Green fill | B6: LIVE FORMULA. Recomputed in this workbook from the raw inputs in the same row or sheet. Changing an input recalculates the result.
A7: Orange fill | B7: Locator block — document, label, section, subsection and printed page for the table that follows.
A8: Red-orange fill | B8: Variance, QA flag or unresolved item. Requires resolution before the figure is used for allocation.
A10: HOW TO READ THE SHEETS
A11: 01_Source_Register | B11: The five documents, their Google Doc IDs and links, coverage, evidence base and status as declared in each report's REPORT PARTICULARS block.
A12: 02_Section_Index | B12: Every numbered section and subsection of all five reports with the printed page number carried by that report's own contents list.
A13: 03_Table_Index | B13: Every table, exhibit and annex across the five reports: label, printed title, section number, subsection number, printed page, dimensions, source note, and the domain sheet where its data sits.
A14: 04_Report_Particulars | B14: Each report's own REPORT PARTICULARS block: who prepared it, under what programme, its declared coverage, its declared evidence base and package, and its declared status.
A15: 05_Assumptions | B15: The planning parameters the live formulas depend on — the 1:20,000 catchment standard, the rounding convention for implied units, the bed-rate denominator and the population base year. Edit the yellow cells and every dependent sheet recalculates.
A16: 10_Municipal_Master (live) | B16: The four LGU-level annex master tables harmonised into one register of 84 local government units plus Cotabato City, with live recomputation of population per rural health unit, the 1:20,000 implied requirement and shortfall, barangay coverage and beds per 1,000.
A17: 11 to 16 (live) | B17: Thematic recomputation sheets: jurisdiction roll-ups, PhilHealth accreditations, the Konsulta return, inpatient capacity, cold chain, the 1:20,000 standard, and the first-contact coverage gradient. Each carries the figure as printed alongside the live recomputation and the variance.
A18: D01 to D14 | B18: Every remaining table reproduced verbatim, grouped by subject domain, each under its locator block.
A19: 90_QA_Flags | B19: Numbering defects, duplicated labels, missing tables, denominator conflicts and cross-document divergences found during extraction.
A20: 91_Metadata_Dictionary | B20: Field definitions, units, bases and source layers.
A22: STANDING LIMITATIONS CARRIED FROM THE SOURCES
A23: Status | B23: All five reports are declared PROVISIONAL by their own particulars blocks. They establish cleaned service-location baselines, not validated registers of distinct licensed facilities.
A24: Registers | B24: Facility identity, classification, ownership, licensing and accreditation remain subject to reconciliation with MOH-BARMM, DOH-HFSRB and PhilHealth records.
A25: Denominators | B25: Barangay denominators are not consistent across documents. Lanao del Sur's annex preserves the 1,159-node 2020 model geography while current administrative coverage is 1,164 barangays; a five-barangay crosswalk is outstanding.
A26: Page numbers | B26: Page numbers are those printed in each document's own contents list at the time of export. They will move if the documents are repaginated. Section, subsection and table labels are the stable locators and are carried in every row.
A27: Do not use for | B27: Allocation, procurement or costing decisions until the QA flags on sheet 90 are closed.

Sheet 01_Source_Register
A1: Code | B1: Report title | C1: Google Doc file name | D1: Google Doc ID | E1: Link | F1: Scope / unit of analysis | G1: Coverage as declared | H1: Prepared by | I1: Prepared under | J1: Evidence base as declared | K1: Status as declared | L1: Export characters | M1: Export lines | N1: Sections captured | O1: Tables captured | P1: Export basis
A2: BARMM | B2: BARMM Regional Health Systems Diagnostic | C2: BARMM_Regional_Health_Systems_Diagnostic_2026 | D2: 1dzIeIl6jTtxzQXwrF24ZUHT6uOuRUBZV8E55xVY0pFU | E2: https://docs.google.com/document/d/1dzIeIl6jTtxzQXwrF24ZUHT6uOuRUBZV8E55xVY0pFU/edit | F2: Region-wide consolidation of four jurisdiction volumes | G2: 84 local government units, 1,735 current barangays and 3,137,511 residents in four jurisdictions. This is 69.0 per cent of the current PSA BARMM planning population. Basilan, Tawi-Tawi and Cotabato City are outside the workshop cycle; Sulu is outside the cycle and current BARMM. | H2: Lawrence John Paulo L. Trinidad · Consultant, International Organization for Migration (IOM) | I2: Building Resilience through Inclusive Governance and Healthcare Transformation in BARMM (BRIGHT-BARMM), a five-year initiative, 2025–2030 | J2: PSA 2024 Census and current PSGC; 2022 NDHS historical baseline; 2025 NDHS current regional key indicators; municipal scorecards; facility register; dated PhilHealth/Konsulta returns requiring current YAKAP verification; MOH-BARMM FHSIS assessment; WHO, World Bank and workshop records. | K2: Provisional. This consolidation carries forward the provisional status of all four volumes. No figure in it is validated beyond the validation each volume states its own figures require, and no figure in it should be used for allocation or procurement before the ninety-day programmes at Annex B are complete. | L2: 167357 | M2: 1004 | N2: 59 | O2: 27 | P2: 2026-08-11 (Asia/Manila) — Google Docs text export via Google Drive connector
A3: LDS | B3: Lanao del Sur Provincial Health Systems Diagnostic | C3: Lanao_del_Sur_Provincial_Health_Systems_Diagnostic_2026 | D3: 1iZhI2yG39xlDHiQUGLeSOtYpXfam9joZxB5eLtAqRU0 | E3: https://docs.google.com/document/d/1iZhI2yG39xlDHiQUGLeSOtYpXfam9joZxB5eLtAqRU0/edit | F3: Province of Lanao del Sur (40 LGUs incl. Marawi City) | G3: Seventeen (17) local government units of Lanao del Sur participating in the Evidence-Based Decision-Making (EBDM) workshop cycle | H3: Lawrence John Paulo L. Trinidad · Consultant, International Organization for Migration (IOM) | I3: Building Resilience through Inclusive Governance and Healthcare Transformation in BARMM (BRIGHT-BARMM) | J3: Municipal and provincial EBDM worksheet submissions (BARMM 20260629 package), audited into 442 raw rows, 407 cleaned service-location records and 174 records with named or typed facility evidence. Facility identity, classification, accreditation and cold-chain assets remain subject to reconciliation with MOH-BARMM/DOH, PhilHealth and local records. | K3: Provisional. The revision establishes a cleaned service-location baseline, not a validated count of distinct facilities. Registry reconciliation and field verification remain required before allocation or procurement. | L3: 172890 | M3: 1270 | N3: 57 | O3: 32 | P3: 2026-08-11 (Asia/Manila) — Google Docs text export via Google Drive connector
A4: MDN | B4: Maguindanao del Norte Provincial Health Systems Diagnostic | C4: Maguindanao_del_Norte_Provincial_Health_Systems_Diagnostic_2026 | D4: 1JLHwqdyuaFspWyMZVIoNMDLXeGYt1dX5ot2H6V5AST4 | E4: https://docs.google.com/document/d/1JLHwqdyuaFspWyMZVIoNMDLXeGYt1dX5ot2H6V5AST4/edit | F4: Province of Maguindanao del Norte (12 municipalities); Cotabato City shown separately | G4: Twelve (12) constituent municipalities of Maguindanao del Norte — the full complement of the province — participating in the Evidence-Based Decision-Making (EBDM) workshop cycle, together with the City of Cotabato, which participated as an adjunct reporting entity and is not a component local government unit of the province. | H4: Lawrence John Paulo L. Trinidad · Consultant, International Organization for Migration (IOM) | I4: Building Resilience through Inclusive Governance and Healthcare Transformation in BARMM (BRIGHT-BARMM) | J4: Municipal EBDM worksheet submissions (BARMM 20260629 package), audited into 300 raw rows, 230 rows attributable to the twelve constituent municipalities and 207 cleaned service-location records after removal of echo and padding rows. Forty-seven further rows belong to the City of Cotabato and twenty-three to Datu Paglas, a Maguindanao del Sur municipality misfiled in the provincial workbook. Read against the national facility registry (224 records in the twelve municipalities), the DOH LGU Health Scorecard municipal dataset, the MOH-BARMM FHSIS assessment and PhilHealth returns. | K4: Provisional. The report establishes a reconciled service-location baseline and a first municipal master table for a province created in 2022 and not yet carried as a separate reporting unit in most national datasets. Registry reconciliation, denominator validation and field verification remain required before allocation or procurement. | L4: 176250 | M4: 1226 | N4: 53 | O4: 33 | P4: 2026-08-11 (Asia/Manila) — Google Docs text export via Google Drive connector
A5: MDS | B5: Maguindanao del Sur Provincial Health Systems Diagnostic | C5: Maguindanao_del_Sur_Provincial_Health_Systems_Diagnostic_2026 | D5: 1hd1i9nx9ABMeMfDunmPezHI4grylzYzKH7RTHT2HG7Q | E5: https://docs.google.com/document/d/1hd1i9nx9ABMeMfDunmPezHI4grylzYzKH7RTHT2HG7Q/edit | F5: Province of Maguindanao del Sur (24 municipalities) | G5: The twenty-four (24) constituent municipalities of Maguindanao del Sur enumerated in Republic Act No. 11550, §3(b); 287 barangays; 813,243 residents at the 2024 Census | H5: Lawrence John Paulo L. Trinidad · Consultant, International Organization for Migration (IOM) | I5: Building Resilience through Inclusive Governance and Healthcare Transformation in BARMM (BRIGHT-BARMM) | J5: Official statistics for all 24 municipalities (PSA 2024 Census; DOH LGU Health Scorecard; the 222-record DOH/HFSRB facility register; PhilHealth returns of July 2024; the MOH-BARMM FHSIS assessment) tested against the EBDM workshop record filed by 21 of 24 local government units. Facility identity, classification, accreditation, workforce and revenue fields remain subject to reconciliation with MOH-BARMM/DOH, PhilHealth and local records. | K5: Provisional. This edition establishes a municipality-level baseline on official sources. It does not adopt the provincial dashboard circulated in the 20260624/20260629 package, which represents two of twenty-four municipalities and is treated in §2.5 as a reconciliation item to be corrected before use as evidence. | L5: 164015 | M5: 1133 | N5: 58 | O5: 27 | P5: 2026-08-11 (Asia/Manila) — Google Docs text export via Google Drive connector
A6: SGA | B6: Special Geographic Area Health Systems Diagnostic | C6: Special_Geographic_Area_Health_Systems_Diagnostic_2026 | D6: 1sc7EG9QPVDd5x_zTKnJbfOmBXOYgAdCbretmVNW1PE0 | E6: https://docs.google.com/document/d/1sc7EG9QPVDd5x_zTKnJbfOmBXOYgAdCbretmVNW1PE0/edit | F6: Special Geographic Area, PSGC 1999900000 (8 municipalities) | G6: The Special Geographic Area (PSGC 1999900000): eight municipalities, 63 barangays, 214,703 residents at the 2024 Census of Population. All eight municipalities are inside the evidence base. There is no absent cohort. | H6: Evidence-Based Decision-Making workstream, BRIGHT-BARMM, International Organization for Migration. | I6: The Executive Workshop on Evidence-Based Decision Making for Local Health Leaders (BRIGHT BARMM). | J6: Municipal EBDM worksheet submissions (BARMM 20260629 package), audited into 105 raw rows and 66 cleaned service-location records; the project-held DOH facility register (68 Special Geographic Area registrations); the MOH-BARMM FHSIS unit assessment (two of eight municipalities); the draft 2024 BARMM LGU Health Scorecard; PhilHealth's July 2024 returns to IOM; and the World Bank BARMM household survey, North Cotabato stratum. Facility identity, classification, ownership, licensing and accreditation remain subject to reconciliation with MOH-BARMM, DOH-HFSRB and PhilHealth records. | K6: Provisional. The report establishes a cleaned service-location baseline reconciled to the 2024 Census, not a validated register of distinct licensed facilities. Registry reconciliation, licensure verification and field validation remain required before allocation or procurement. | L6: 176673 | M6: 1228 | N6: 53 | O6: 29 | P6: 2026-08-11 (Asia/Manila) — Google Docs text export via Google Drive connector

Sheet 02_Section_Index
A1: Report | B1: Level | C1: Section no. | D1: Section / subsection title | E1: Printed page (document contents list) | F1: Parent section no. | G1: Parent section title | H1: Entry as printed
A2: BARMM | B2: Section | C2: 1 | D2: Executive Summary | E2: 4 | H2: 1 Executive Summary 4
A3: BARMM | B3: Subsection | D3: The central assessment | E3: 4 | F3: 1 | G3: Executive Summary | H3: The central assessment 4
A4: BARMM | B4: Subsection | D4: Eight findings | E4: 4 | F4: 1 | G4: Executive Summary | H4: Eight findings 4
A5: BARMM | B5: Subsection | D5: Decisions required of the Ministry | E5: 6 | F5: 1 | G5: Executive Summary | H5: Decisions required of the Ministry 6
A6: BARMM | B6: Section | C6: 2 | D6: Scope, Evidence and Method | E6: 9 | H6: 2 Scope, Evidence and Method 9
A7: BARMM | B7: Subsection | D7: What this consolidation is, and what it is not | E7: 9 | F7: 2 | G7: Scope, Evidence and Method | H7: What this consolidation is, and what it is not 9
A8: BARMM | B8: Subsection | D8: The evidence layers, consolidated | E8: 9 | F8: 2 | G8: Scope, Evidence and Method | H8: The evidence layers, consolidated 9
A9: BARMM | B9: Subsection | D9: The reconciliation rules carried forward | E9: 10 | F9: 2 | G9: Scope, Evidence and Method | H9: The reconciliation rules carried forward 10
A10: BARMM | B10: Subsection | D10: Relation to the superseded regional draft of 6 August 2026 | E10: 10 | F10: 2 | G10: Scope, Evidence and Method | H10: Relation to the superseded regional draft of 6 August 2026 10
A11: BARMM | B11: Section | C11: 3 | D11: Four Jurisdictions, Four Constraints | E11: 11 | H11: 3 Four Jurisdictions, Four Constraints 11
A12: BARMM | B12: Section | C12: 4 | D12: Stage One — The Illness | E12: 13 | H12: 4 Stage One — The Illness 13
A13: BARMM | B13: Subsection | D13: What the record does not yet support on mortality | E13: 13 | F13: 4 | G13: Stage One — The Illness | H13: What the record does not yet support on mortality 13
A14: BARMM | B14: Subsection | D14: The non-communicable disease loop | E14: 13 | F14: 4 | G14: Stage One — The Illness | H14: The non-communicable disease loop 13
A15: BARMM | B15: Subsection | D15: Tuberculosis: one detection ratio, three provinces | E15: 14 | F15: 4 | G15: Stage One — The Illness | H15: Tuberculosis: one detection ratio, three provinces 14
A16: BARMM | B16: Subsection | D16: The measles outbreak as arbitration | E16: 14 | F16: 4 | G16: Stage One — The Illness | H16: The measles outbreak as arbitration 14
A17: BARMM | B17: Section | C17: 5 | D17: Stage Two — First Contact | E17: 16 | H17: 5 Stage Two — First Contact 16
A18: BARMM | B18: Subsection | D18: The coverage gradient | E18: 16 | F18: 5 | G18: Stage Two — First Contact | H18: The coverage gradient 16
A19: BARMM | B19: Subsection | D19: The 1:20,000 standard is not a facility standard | E19: 16 | F19: 5 | G19: Stage Two — First Contact | H19: The 1:20,000 standard is not a facility standard 16
A20: BARMM | B20: Subsection | D20: The cold chain is not yet assessable from the record | E20: 17 | F20: 5 | G20: Stage Two — First Contact | H20: The cold chain is not yet assessable from the record 17
A21: BARMM | B21: Subsection | D21: Isolation is not yet measured in three of four jurisdictions | E21: 17 | F21: 5 | G21: Stage Two — First Contact | H21: Isolation is not yet measured in three of four jurisdictions 17
A22: BARMM | B22: Section | C22: 6 | D22: Stage Three — Payment | E22: 18 | H22: 6 Stage Three — Payment 18
A23: BARMM | B23: Subsection | D23: The perimeter | E23: 18 | F23: 6 | G23: Stage Three — Payment | H23: The perimeter 18
A24: BARMM | B24: Subsection | D24: The throughput not yet computable | E24: 18 | F24: 6 | G24: Stage Three — Payment | H24: The throughput not yet computable 18
A25: BARMM | B25: Subsection | D25: The area absent from the current line item | E25: 19 | F25: 6 | G25: Stage Three — Payment | H25: The area absent from the current line item 19
A26: BARMM | B26: Subsection | D26: What the household pays | E26: 19 | F26: 6 | G26: Stage Three — Payment | H26: What the household pays 19
A27: BARMM | B27: Section | C27: 7 | D27: Stage Four — Referral | E27: 21 | H27: 7 Stage Four — Referral 21
A28: BARMM | B28: Subsection | D28: The inpatient stock | E28: 21 | F28: 7 | G28: Stage Four — Referral | H28: The inpatient stock 21
A29: BARMM | B29: Subsection | D29: Three different ownership exposures | E29: 21 | F29: 7 | G29: Stage Four — Referral | H29: Three different ownership exposures 21
A30: BARMM | B30: Subsection | D30: The referral measurement gap | E30: 22 | F30: 7 | G30: Stage Four — Referral | H30: The referral measurement gap 22
A31: BARMM | B31: Subsection | D31: The service-delivery network document not yet located | E31: 22 | F31: 7 | G31: Stage Four — Referral | H31: The service-delivery network document not yet located 22
A32: BARMM | B32: Section | C32: 8 | D32: Stage Five — Follow-Up and the Record | E32: 24 | H32: 8 Stage Five — Follow-Up and the Record 24
A33: BARMM | B33: Subsection | D33: The FHSIS apparatus | E33: 24 | F33: 8 | G33: Stage Five — Follow-Up and the Record | H33: The FHSIS apparatus 24
A34: BARMM | B34: Subsection | D34: The instrument requires repair | E34: 24 | F34: 8 | G34: Stage Five — Follow-Up and the Record | H34: The instrument requires repair 24
A35: BARMM | B35: Subsection | D35: Civil registration and the invisible denominator | E35: 25 | F35: 8 | G35: Stage Five — Follow-Up and the Record | H35: Civil registration and the invisible denominator 25
A36: BARMM | B36: Section | C36: 9 | D36: The Reconciliation | E36: 26 | H36: 9 The Reconciliation 26
A37: BARMM | B37: Subsection | D37: What the divergence means for regional allocation | E37: 26 | F37: 9 | G37: The Reconciliation | H37: What the divergence means for regional allocation 26
A38: BARMM | B38: Section | C38: 10 | D38: The Evidence Pipeline | E38: 28 | H38: 10 The Evidence Pipeline 28
A39: BARMM | B39: Section | C39: A | D39: catalogue of data-build issues | E39: 28 | H39: A catalogue of data-build issues 28
A40: BARMM | B40: Subsection | D40: The composite score | E40: 28 | F40: A | G40: catalogue of data-build issues | H40: The composite score 28
...

Sheet 03_Table_Index
A1: Report | B1: Label | C1: Printed title / caption | D1: Section no. | E1: Section title | F1: Subsection no. | G1: Subsection title | H1: Printed page | I1: Rows (data) | J1: Columns | K1: Domain sheet | L1: Domain | M1: Source note as printed | N1: Export line no.
A2: BARMM | B2: (unlabelled) | C2: # 1 Executive Summary | D2: 1 | E2: Executive Summary | H2: 4 | I2: 0 | J2: 7 | K2: D01 | L2: Executive summary and headline panels | N2: 182
A3: BARMM | B3: (unlabelled) | C3: | 84local government units infour jurisdictions | | 3,137,511 residents, 2024 Census — 55.1% of the 1 July 2024 BARMM-with-Sulu total; 69.0% of current BARMM | | 1,735 current barangays | | 756registered health facilitieson the registry basis | | D3: 1 | E3: Executive Summary | H3: 4 | I3: 0 | J3: 7 | K3: D04 | L3: First contact, facilities and catchment | N3: 188
A4: BARMM | B4: EXHIBIT 1 | C4: Four jurisdictions, four distinct constraints, three shared findings | D4: 1 | E4: Executive Summary | G4: Eight findings | H4: 4 | I4: 5 | J4: 4 | K4: D02 | L4: Evidence base, scope and method | N4: 220
A5: BARMM | B5: TABLE 1 | C5: The four volumes at a glance | D5: 2 | E5: Scope, Evidence and Method | G5: What this consolidation is, and what it is not | H5: 9 | I5: 5 | J5: 6 | K5: D02 | L5: Evidence base, scope and method | N5: 267
A6: BARMM | B6: TABLE 2 | C6: The evidence layers and what each can carry across four jurisdictions | D6: 2 | E6: Scope, Evidence and Method | G6: The evidence layers, consolidated | H6: 9 | I6: 5 | J6: 5 | K6: D02 | L6: Evidence base, scope and method | N6: 284
A7: BARMM | B7: EXHIBIT 2 | C7: The regional dashboard: what each jurisdiction can and cannot measure | D7: 3 | E7: Four Jurisdictions, Four Constraints | H7: 11 | I7: 16 | J7: 6 | K7: D02 | L7: Evidence base, scope and method | N7: 319
A8: BARMM | B8: TABLE 3 | C8: What the evidence establishes, and does not establish, about disease burden | D8: 4 | E8: Stage One — The Illness | G8: What the record does not yet support on mortality | H8: 13 | I8: 6 | J8: 3 | K8: D03 | L8: Disease burden and service coverage | N8: 353
A9: BARMM | B9: EXHIBIT 3 | C9: Adults risk-assessed under PhilPEN, by jurisdiction | D9: 4 | E9: Stage One — The Illness | G9: The non-communicable disease loop | H9: 13 | I9: 4 | J9: 5 | K9: D03 | L9: Disease burden and service coverage | N9: 377
A10: BARMM | B10: EXHIBIT 4 | C10: The first-contact coverage gradient: 11 per cent to 100 per cent | D10: 5 | E10: Stage Two — First Contact | G10: The coverage gradient | H10: 16 | I10: 4 | J10: 6 | K10: D04 | L10: First contact, facilities and catchment | N10: 409
A11: BARMM | B11: TABLE 4 | C11: Rural health units against the 1:20,000 planning target | D11: 5 | E11: Stage Two — First Contact | G11: The 1:20,000 standard is not a facility standard | H11: 16 | I11: 5 | J11: 6 | K11: D04 | L11: First contact, facilities and catchment | N11: 425
A12: BARMM | B12: EXHIBIT 5 | C12: Cold chain: 115 functional, 353 not stated, out of 836 records | D12: 5 | E12: Stage Two — First Contact | G12: The cold chain is not yet assessable from the record | H12: 16 | I12: 5 | J12: 6 | K12: D05 | L12: Cold chain and commodities | N12: 444
A13: BARMM | B13: TABLE 5 | C13: PhilHealth-accredited health care institutions, BARMM by province | D13: 6 | E13: Stage Three — Payment | G13: The perimeter | H13: 18 | I13: 12 | J13: 10 | K13: D06 | L13: Payment, PhilHealth and financing | N13: 471
A14: BARMM | B14: TABLE 6 | C14: The PhilHealth Konsulta return, and its three arithmetic failures | D14: 6 | E14: Stage Three — Payment | G14: The throughput not yet computable | H14: 18 | I14: 9 | J14: 6 | K14: D06 | L14: Payment, PhilHealth and financing | N14: 499
A15: BARMM | B15: TABLE 7 | C15: Licensed inpatient capacity across the four jurisdictions | D15: 7 | E15: Stage Four — Referral | G15: The inpatient stock | H15: 21 | I15: 5 | J15: 8 | K15: D07 | L15: Referral and inpatient capacity | N15: 532
A16: BARMM | B16: EXHIBIT 6 | C16: The referral measurement gap: zero observations across 57 reporting units | D16: 7 | E16: Stage Four — Referral | G16: The referral measurement gap | H16: 21 | I16: 5 | J16: 5 | K16: D07 | L16: Referral and inpatient capacity | N16: 565
A17: BARMM | B17: TABLE 8 | C17: The condition of routine reporting: 68 assessed units | D17: 8 | E17: Stage Five — Follow-Up and the Record | G17: The FHSIS apparatus | H17: 24 | I17: 13 | J17: 6 | K17: D08 | L17: Routine reporting, FHSIS and civil registration | N17: 588
A18: BARMM | B18: EXHIBIT 7 | C18: Five divergences between the administrative record and independent measurement | D18: 9 | E18: The Reconciliation | H18: 26 | I18: 5 | J18: 4 | K18: D09 | L18: Reconciliation and divergences | N18: 631
A19: BARMM | B19: TABLE 9 | C19: The parser and build issues, by jurisdiction | D19: 10 | E19: The Evidence Pipeline | G19: A catalogue of data-build issues | H19: 28 | I19: 7 | J19: 4 | K19: D02 | L19: Evidence base, scope and method | N19: 660
A20: BARMM | B20: TABLE 10 | C20: Legal obligations engaged by the consolidated findings | D20: 11 | E20: Governance and Legal Framework | H20: 30 | I20: 9 | J20: 4 | K20: D10 | L20: Governance and legal framework | N20: 691
A21: BARMM | B21: EXHIBIT 8 | C21: Sequencing: what the Ministry must settle before anything else can be sized | D21: 12 | E21: Priorities: sequencing the Ministry’s own decisions | H21: 32 | I21: 7 | J21: 5 | K21: D11 | L21: Priorities and sequencing | N21: 736
A22: BARMM | B22: EXHIBIT 9 | C22: Regional volumetrics for the two-year programme | D22: 13 | E22: Two-Year Investment Logic, 2026–2028 | G22: Regional volumetrics | H22: 33 | I22: 13 | J22: 3 | K22: D12 | L22: Investment logic and volumetrics | N22: 761
A23: BARMM | B23: TABLE 11 | C23: The two-year programme: volumetrics, sequencing and financing route | D23: 13 | E23: Two-Year Investment Logic, 2026–2028 | G23: The programme | H23: 33 | I23: 11 | J23: 5 | K23: D12 | L23: Investment logic and volumetrics | N23: 784
A24: BARMM | B24: TABLE 12 | C24: Regional monitoring indicators | D24: 14 | E24: Monitoring Framework | H24: 35 | I24: 14 | J24: 5 | K24: D13 | L24: Monitoring indicators | N24: 815
A25: BARMM | B25: ANNEX A | C25: # A Annex A — Jurisdiction master table | D25: A | E25: Annex A — Jurisdiction master table | H25: 28 | I25: 5 | J25: 16 | K25: D14 | L25: Annexes, master tables and gap registers | N25: 918
A26: BARMM | B26: ANNEX B | C26: Each of the four volumes carries its own validation programme, structured for completion within ninety days of adoption by the responsible health board, and none requires capital expenditure. The table consolidates the twenty-nine tasks in those four programmes into nineteen, and separates what the jurisdictions owe from what the Ministry owes. Ten of the nineteen require Ministry initiation or coordination; those are the rows prefixed M, and the four capital programmes are contingent on them. | D26: B | E26: Annex B — Consolidated ninety-day programme | H26: 39 | I26: 19 | J26: 6 | K26: D14 | L26: Annexes, master tables and gap registers | N26: 934
A27: BARMM | B27: ANNEX C | C27: Sixty items are recorded across the four volumes’ own gap registers. The fourteen below are those that recur in two or more jurisdictions, or that a single jurisdiction identifies as decisive. They are ordered by consequence. Twelve of the fourteen are documents retrievable by written request; two require field collection; none requires a new research design. | D27: C | E27: Annex C — Regional evidence gap register | H27: 41 | I27: 14 | J27: 4 | K27: D14 | L27: Annexes, master tables and gap registers | N27: 964
A28: BARMM | B28: ANNEX D | C28: The four volumes were built sequentially and each corrected findings in its predecessors. Eleven divergences remain unresolved between them. They are recorded here rather than adjudicated, because resolving them requires a source the consolidation does not hold. Item 2 is load-bearing: it determines whether any jurisdiction in the series can state its leading causes of death. | D28: D | E28: Annex D — Divergences between the four volumes | H28: 42 | I28: 11 | J28: 5 | K28: D14 | L28: Annexes, master tables and gap registers | N28: 989
A29: LDS | B29: (unlabelled) | C29: # 1 Executive Summary | D29: 1 | E29: Executive Summary | H29: 4 | I29: 0 | J29: 7 | K29: D01 | L29: Executive summary and headline panels | N29: 190
A30: LDS | B30: (unlabelled) | C30: | 11licensed hospitals | | D30: 1 | E30: Executive Summary | H30: 4 | I30: 0 | J30: 7 | K30: D07 | L30: Referral and inpatient capacity | N30: 202
A31: LDS | B31: EXHIBIT 1 | C31: The five stages, and what fails at each one | D31: 1 | E31: Executive Summary | G31: Six findings | H31: 4 | I31: 5 | J31: 4 | K31: D01 | L31: Executive summary and headline panels | M31: Note. Each claim is evidenced in the section indicated. Adapted from Philippine Statistics Authority (2025c); Philippine Statistics Authority and ICF (2023); Department of Health (n.d.-a, 2020b, 2022); Philippine Health Insurance Corporation (2024); World Bank (2019); and International Organization for Migration (2026a). | N31: 241
A32: LDS | B32: TABLE 2 | C32: Completion of required worksheet outputs across the cohort | D32: 2 | E32: Program, Scope, Evidence and Method | H32: 8 | I32: 4 | J32: 4 | K32: D02 | L32: Evidence base, scope and method | N32: 274
A33: LDS | B33: TABLE 1 | C33: The five evidence layers and what each can carry | D33: 2 | E33: Program, Scope, Evidence and Method | F33: 2.2 | G33: The five evidence layers | H33: 8 | I33: 5 | J33: 5 | K33: D02 | L33: Evidence base, scope and method | N33: 292
A34: LDS | B34: (unlabelled) | C34: The 407 cleaned service-location records filed by fifteen local government units, resolved into three components. Source: EBDM worksheet package, 20260629. | D34: 2 | E34: Program, Scope, Evidence and Method | F34: 2.4 | G34: From the Executive Workshop on Evidence-based Decision Making (BRIGHT BARMM) | H34: 9 | I34: 0 | J34: 2 | K34: D02 | L34: Evidence base, scope and method | N34: 320
A35: LDS | B35: TABLE 2 | C35: Leading causes of morbidity and mortality, Lanao del Sur | D35: 3 | E35: Stage One — The Illness | F35: 3.1 | G35: The provincial cause profile | H35: 11 | I35: 10 | J35: 4 | K35: D03 | L35: Disease burden and service coverage | M35: Note. Adapted from World Bank (2019, Table 41, p. 113), reporting Department of Health–ARMM data. Bold entries are non-communicable or trauma causes. No year is stated for the underlying data; the source notes that collection took place during the conflict period, and the profile should be treated as circa 2016–2018. | N35: 340
A36: LDS | B36: EXHIBIT 2 | C36: Child deaths in BARMM fall after the first month rather than during it | D36: 3 | E36: Stage One — The Illness | F36: 3.2 | G36: The child-survival signature | H36: 12 | I36: 0 | J36: 2 | K36: D03 | L36: Disease burden and service coverage | M36: Note. Deaths per 1,000 live births. Adapted from Philippine Statistics Authority and ICF (2023, Tables 8.1 and 8.3). The figures are historical 2022 regional estimates: BARMM rates use a ten-year reference period, while national comparators use five years. Under-five mortality was 28 per 1,000. In the published tables, 98 children and 188 births are weighted denominators; 180 children and 345 births are the corresponding unweighted cases. The latest 2025 NDHS key indicators do not provide an updated regional child-mortality series. | N36: 372
A37: LDS | B37: EXHIBIT 4 | C37: The measles chain: a survey finding, an outbreak, and thirteen deaths | D37: 3 | E37: Stage One — The Illness | F37: 3.4 | G37: The 2023–2024 measles outbreak | H37: 15 | I37: 8 | J37: 4 | K37: D03 | L37: Disease burden and service coverage | M37: Note. Adapted from Philippine Statistics Authority and ICF (2023, Table 10.4.2); Department of Health (n.d.-a); UNICEF Philippines (2024); and Bangsamoro Information Office (2024). The Provincial Health Officer II of Lanao del Sur is quoted attributing the outbreak to “the decline of our immunization rate here in Lanao del Sur” (Bangsamoro Information Office, 2024). The Regional Darul Ifta’ issued a fatwa declaring the vaccines halal — a documented and replicable demand-side intervention. | N37: 416
A38: LDS | B38: (unlabelled) | C38: Facility counts and travel times answer different questions, and the province needs both. A registration is not a building, a building within reach is not an open service, and an open service is not necessarily ready to treat the patient in front of it. The multimodal accessibility model of 8 August 2026 separates these questions for the first time. Its central result is that physical proximity is not, on the assumptions used, the constraint that binds for most of Lanao del Sur. Section 4.3 sets out a consistency test that qualifies how far that result can be carried. | D38: 4 | E38: Primary-Care Access: physical, effective and registered | F38: 4.0 | G38: Physical and effective access: what the model establishes | H38: 17 | I38: 0 | J38: 5 | K38: D04 | L38: First contact, facilities and catchment | M38: Note. Adapted from the Lanao del Sur multimodal and effective primary-care accessibility model (International Organization for Migration, 2026b). Population uses the GeoRisk/PSA 2020 modeled base of 1,195,518 across 1,159 demand nodes against 184 barangay health station and rural health unit supply points. The supply set requires reconciliation: the project-held facility register carries 128 barangay health stations and 44 rural health units, or 172 supply points, and the derivation of the further 12 used by the model is not documented in the material reviewed. The 2024 equivalent of the physical gap is 132,217 by proportional scaling to 1,368,137; it is not a barangay-level 2024 measurement. | N38: 450
A39: LDS | B39: TABLE A | C39: The modeled gap does not vary with facility supply | D39: 4 | E39: Primary-Care Access: physical, effective and registered | F39: 4.3 | G39: A consistency test of the modeled result | H39: 20 | I39: 3 | J39: 3 | K39: D04 | L39: First contact, facilities and catchment | M39: Note. Computed for this report across all 40 local government units, from the central 30-minute multimodal scenario (International Organization for Migration, 2026b) against the project-held facility register and the DOH GIDA barangay register (Department of Health, 2022). A facility-driven access result would show a positive association with barangays per supply point; the observed association is negative on both measures. The strongest association in the set is with geographic isolation. | N39: 500
A40: LDS | B40: (unlabelled) | C40: Physical reach is a necessary condition, not a sufficient one. The model applies a readiness credit to a supply point only where the workshop record provides a direct municipality-and-barangay match and at least half of the planned readiness dimensions were observed — service inventory, workforce, equipment, cold chain, PhilHealth status and referral turnaround. Fifty-nine supply points have a direct match; fifty-seven meet the credit threshold. | D40: 4 | E40: Primary-Care Access: physical, effective and registered | F40: 4.4 | G40: Effective access, and the population the province cannot yet assess | H40: 22 | I40: 0 | J40: 7 | K40: D07 | L40: Referral and inpatient capacity | M40: Note. Adapted from International Organization for Migration (2026b). Municipality profiles inform prioritization but do not impute facility-level credit. | N40: 529
...

Sheet 04_Report_Particulars
A1: Report | B1: Field | C1: Value as declared in the report
A2: BARMM | B2: Prepared by | C2: Lawrence John Paulo L. Trinidad · Consultant, International Organization for Migration (IOM)
A3: BARMM | B3: Prepared under | C3: Building Resilience through Inclusive Governance and Healthcare Transformation in BARMM (BRIGHT-BARMM), a five-year initiative, 2025–2030
A4: BARMM | B4: Program partners | C4: KOICA and IOM, in partnership with the Ministry of Health, BARMM
A5: BARMM | B5: Coverage | C5: 84 local government units, 1,735 current barangays and 3,137,511 residents in four jurisdictions. This is 69.0 per cent of the current PSA BARMM planning population. Basilan, Tawi-Tawi and Cotabato City are outside the workshop cycle; Sulu is outside the cycle and current BARMM.
A6: BARMM | B6: Evidence base | C6: PSA 2024 Census and current PSGC; 2022 NDHS historical baseline; 2025 NDHS current regional key indicators; municipal scorecards; facility register; dated PhilHealth/Konsulta returns requiring current YAKAP verification; MOH-BARMM FHSIS assessment; WHO, World Bank and workshop records.
A7: BARMM | B7: Status | C7: Provisional. This consolidation carries forward the provisional status of all four volumes. No figure in it is validated beyond the validation each volume states its own figures require, and no figure in it should be used for allocation or procurement before the ninety-day programmes at Annex B are complete.
A8: LDS | B8: Prepared by | C8: Lawrence John Paulo L. Trinidad · Consultant, International Organization for Migration (IOM)
A9: LDS | B9: Prepared under | C9: Building Resilience through Inclusive Governance and Healthcare Transformation in BARMM (BRIGHT-BARMM)
A10: LDS | B10: Program partners | C10: Korea International Cooperation Agency (KOICA) and the International Organization for Migration (IOM), in partnership with the Ministry of Health, Bangsamoro Autonomous Region in Muslim Mindanao (MOH-BARMM)
A11: LDS | B11: Coverage | C11: Seventeen (17) local government units of Lanao del Sur participating in the Evidence-Based Decision-Making (EBDM) workshop cycle
A12: LDS | B12: Evidence base | C12: Municipal and provincial EBDM worksheet submissions (BARMM 20260629 package), audited into 442 raw rows, 407 cleaned service-location records and 174 records with named or typed facility evidence. Facility identity, classification, accreditation and cold-chain assets remain subject to reconciliation with MOH-BARMM/DOH, PhilHealth and local records.
... A31: SGA | B31: Status | C31: Provisional. The report establishes a cleaned service-location baseline reconciled to the 2024 Census, not a validated register of distinct licensed facilities. Registry reconciliation, licensure verification and field validation remain required before allocation or procurement.

Sheet 05_Assumptions
A1: ASSUMPTIONS AND PLANNING PARAMETERS — EDIT THE YELLOW CELLS AND THE WHOLE WORKBOOK RECALCULATES
A3: Parameter | B3: Value | C3: Unit | D3: Basis | E3: What it drives | F3: Convention and caveat
A4: Catchment standard, population per rural health unit | B4: 20000 | C4: residents per unit | D4: The 1:20,000 planning target applied across all five volumes. | E4: Implied rural health units and the shortfall on 10_Municipal_Master, 11_Jurisdiction_Rollup and 16_RHU_Standard_and_Coverage. | F4: The regional volume is explicit that 1:20,000 is a planning target for catchment, not a licensing standard for facilities. It does not by itself justify construction.
A5: Rounding convention for implied units | B5: ROUND (nearest) | C5: convention | D5: Inferred from the source volumes by reconciliation, not stated in them. | E5: The implied-units column on the same three sheets. | F5: Reconciled against Regional Table 4: nearest-integer rounding reproduces 68 / 37 / 41 / 11 exactly, summing to 157. Rounding up would give 69 / 38 / 41 / 11 and a regional 159. Both are computed side by side; the nearest-integer column is the one that reconciles to the reports.
A6: Bed-rate denominator | B6: 1000 | C6: residents | D6: Standard beds-per-1,000 expression used by the volumes. | E6: Beds per 1,000 on 10_Municipal_Master and 14_Inpatient_Capacity.
A7: Population base year | B7: 2024 | C7: year | D7: Philippine Statistics Authority 2024 Census of Population, reference date 1 July 2024. | E7: Every per-capita measure in the workbook. | F7: Facility and service data are of mixed vintage; per-capita rates therefore mix a 2024 denominator with numerators of 2018 to 2026 vintage.

Sheet 10_Municipal_Master
A1: Report | B1: Province / area | C1: Local government unit | D1: Row type | E1: Source locator | F1: Population 2024 | G1: Barangays (as annexed) | H1: Barangays with a first-contact facility (as annexed) | I1: Barangays without a first-contact facility (as annexed) | J1: Rural health units (as annexed) | K1: Barangay health stations | L1: Hospitals | M1: Licensed beds | N1: FIC % | O1: FBD % | P1: TB CNR | Q1: TB detection % | R1: PhilPEN % | S1: Stunting % | T1: Population per RHU as printed | U1: LIVE Population per RHU | V1: LIVE Variance vs printed | W1: LIVE RHUs implied at the catchment standard (nearest) | X1: LIVE RHU shortfall (nearest) | Y1: LIVE Above the catchment standard | Z1: LIVE Barangays with a facility | AA1: LIVE Barangay coverage share | AB1: LIVE Beds per 1,000 residents | AC1: Basis and caveat | AD1: LIVE RHUs implied (rounded up) | AE1: LIVE RHU shortfall (rounded up)
A2: LDS | B2: Lanao del Sur | C2: Marawi City | D2: LGU | E2: LDS · ANNEX A · §A · p. 49 | F2: 259993 | G2: 101 | I2: 70 | J2: 5 | K2: 26 | L2: 4 | N2: 84.5 | O2: 83.8 | P2: 240.2 | Q2: 38 | R2: 10.1 | S2: 5.9 | T2: 51999 | U2: =IF(AND(ISNUMBER(J2),J2>0,ISNUMBER(F2)),F2/J2,"no RHU recorded") -> 51998.6 | V2: =IF(AND(ISNUMBER(T2),ISNUMBER(U2)),U2-T2,"") -> -0.4 | W2: =IF(ISNUMBER(F2),ROUND(F2/'05_Assumptions'!$B$4,0),"") -> 13 | X2: =IF(AND(ISNUMBER(W2),ISNUMBER(J2)),MAX(0,W2-J2),"") -> 8 | Y2: =IF(NOT(ISNUMBER(J2)),"",IF(J2=0,"no RHU",IF(F2/J2>'05_Assumptions'!$B$4,"Yes","No"))) -> Yes | Z2: =IF(ISNUMBER(H2),H2,IF(AND(ISNUMBER(G2),ISNUMBER(I2)),G2-I2,"")) -> 31 | AA2: =IF(AND(ISNUMBER(G2),G2>0,ISNUMBER(Z2)),Z2/G2,"") -> 0.30693069 | AB2: =IF(AND(ISNUMBER(F2),F2>0,ISNUMBER(M2)),M2/F2*'05_Assumptions'!$B$6,"") | AC2: Barangay column preserves the 1,159-node 2020 model geography; current administrative coverage is 1,164 barangays and a five-barangay crosswalk is outstanding. 'Without a facility' = barangays with no matched registered health station. No bed column is carried in this annex. | AD2: =IF(ISNUMBER(F2),ROUNDUP(F2/'05_Assumptions'!$B$4,0),"") -> 13 | AE2: =IF(AND(ISNUMBER(AD2),ISNUMBER(J2)),MAX(0,AD2-J2),"") -> 8
A3: LDS | B3: Lanao del Sur | C3: Malabang | D3: LGU | E3: LDS · ANNEX A · §A · p. 49 | F3: 58377 | G3: 37 | I3: 36 | J3: 1 | K3: 1 | L3: 1 | N3: 111 | O3: 98.5 | P3: 319.6 | Q3: 50.6 | R3: 7 | S3: 1.5 | T3: 58377 | U3: =IF(AND(ISNUMBER(J3),J3>0,ISNUMBER(F3)),F3/J3,"no RHU recorded") -> 58377 | V3: =IF(AND(ISNUMBER(T3),ISNUMBER(U3)),U3-T3,"") -> 0 | W3: =IF(ISNUMBER(F3),ROUND(F3/'05_Assumptions'!$B$4,0),"") -> 3 | X3: =IF(AND(ISNUMBER(W3),ISNUMBER(J3)),MAX(0,W3-J3),"") -> 2 | Y3: =IF(NOT(ISNUMBER(J3)),"",IF(J3=0,"no RHU",IF(F3/J3>'05_Assumptions'!$B$4,"Yes","No"))) -> Yes | Z3: =IF(ISNUMBER(H3),H3,IF(AND(ISNUMBER(G3),ISNUMBER(I3)),G3-I3,"")) -> 1 | AA3: =IF(AND(ISNUMBER(G3),G3>0,ISNUMBER(Z3)),Z3/G3,"") -> 0.027027027 | AB3: =IF(AND(ISNUMBER(F3),F3>0,ISNUMBER(M3)),M3/F3*'05_Assumptions'!$B$6,"") | AC3: Barangay column preserves the 1,159-node 2020 model geography; current administrative coverage is 1,164 barangays and a five-barangay crosswalk is outstanding. 'Without a facility' = barangays with no matched registered health station. No bed column is carried in this annex. | AD3: =IF(ISNUMBER(F3),ROUNDUP(F3/'05_Assumptions'!$B$4,0),"") -> 3 | AE3: =IF(AND(ISNUMBER(AD3),ISNUMBER(J3)),MAX(0,AD3-J3),"") -> 2
A4: LDS | B4: Lanao del Sur | C4: Wao | D4: LGU | E4: LDS · ANNEX A · §A · p. 49 | F4: 51081 | G4: 26 | I4: 0 | J4: 1 | K4: 26 | L4: 1 | N4: 89.6 | O4: 93.2 | P4: 137.9 | Q4: 21.8 | R4: 0.6 | S4: 2.7 | T4: 51081 | U4: =IF(AND(ISNUMBER(J4),J4>0,ISNUMBER(F4)),F4/J4,"no RHU recorded") -> 51081 | V4: =IF(AND(ISNUMBER(T4),ISNUMBER(U4)),U4-T4,"") -> 0 | W4: =IF(ISNUMBER(F4),ROUND(F4/'05_Assumptions'!$B$4,0),"") -> 3 | X4: =IF(AND(ISNUMBER(W4),ISNUMBER(J4)),MAX(0,W4-J4),"") -> 2 | Y4: =IF(NOT(ISNUMBER(J4)),"",IF(J4=0,"no RHU",IF(F4/J4>'05_Assumptions'!$B$4,"Yes","No"))) -> Yes | Z4: =IF(ISNUMBER(H4),H4,IF(AND(ISNUMBER(G4),ISNUMBER(I4)),G4-I4,"")) -> 26 | AA4: =IF(AND(ISNUMBER(G4),G4>0,ISNUMBER(Z4)),Z4/G4,"") -> 1 | AB4: =IF(AND(ISNUMBER(F4),F4>0,ISNUMBER(M4)),M4/F4*'05_Assumptions'!$B$6,"") | AC4: Barangay column preserves the 1,159-node 2020 model geography; current administrative coverage is 1,164 barangays and a five-barangay crosswalk is outstanding. 'Without a facility' = barangays with no matched registered health station. No bed column is carried in this annex. | AD4: =IF(ISNUMBER(F4),ROUNDUP(F4/'05_Assumptions'!$B$4,0),"") -> 3 | AE4: =IF(AND(ISNUMBER(AD4),ISNUMBER(J4)),MAX(0,AD4-J4),"") -> 2
A5: LDS | B5: Lanao del Sur | C5: Lumba-Bayabao | D5: LGU | E5: LDS · ANNEX A · §A · p. 49 | F5: 50959 | G5: 38 | I5: 36 | J5: 1 | K5: 2 | L5: 0 | N5: 95.8 | O5: 99.9 | P5: 104.5 | Q5: 16.5 | R5: 10.4 | S5: 3.4 | T5: 50959 | U5: =IF(AND(ISNUMBER(J5),J5>0,ISNUMBER(F5)),F5/J5,"no RHU recorded") -> 50959 | V5: =IF(AND(ISNUMBER(T5),ISNUMBER(U5)),U5-T5,"") -> 0 | W5: =IF(ISNUMBER(F5),ROUND(F5/'05_Assumptions'!$B$4,0),"") -> 3 | X5: =IF(AND(ISNUMBER(W5),ISNUMBER(J5)),MAX(0,W5-J5),"") -> 2 | Y5: =IF(NOT(ISNUMBER(J5)),"",IF(J5=0,"no RHU",IF(F5/J5>'05_Assumptions'!$B$4,"Yes","No"))) -> Yes | Z5: =IF(ISNUMBER(H5),H5,IF(AND(ISNUMBER(G5),ISNUMBER(I5)),G5-I5,"")) -> 2 | AA5: =IF(AND(ISNUMBER(G5),G5>0,ISNUMBER(Z5)),Z5/G5,"") -> 0.052631579 | AB5: =IF(AND(ISNUMBER(F5),F5>0,ISNUMBER(M5)),M5/F5*'05_Assumptions'!$B$6,"") | AC5: Barangay column preserves the 1,159-node 2020 model geography; current administrative coverage is 1,164 barangays and a five-barangay crosswalk is outstanding. 'Without a facility' = barangays with no matched registered health station. No bed column is carried in this annex. | AD5: =IF(ISNUMBER(F5),ROUNDUP(F5/'05_Assumptions'!$B$4,0),"") -> 3 | AE5: =IF(AND(ISNUMBER(AD5),ISNUMBER(J5)),MAX(0,AD5-J5),"") -> 2
A6: LDS | B6: Lanao del Sur | C6: Marantao | D6: LGU | E6: LDS · ANNEX A · §A · p. 49 | F6: 46233 | G6: 34 | I6: 29 | J6: 1 | K6: 5 | L6: 1 | N6: 89 | O6: 88.4 | P6: 234.3 | Q6: 37.1 | R6: 3.7 | S6: 2.8 | T6: 46233 | U6: =IF(AND(ISNUMBER(J6),J6>0,ISNUMBER(F6)),F6/J6,"no RHU recorded") -> 46233 | V6: =IF(AND(ISNUMBER(T6),ISNUMBER(U6)),U6-T6,"") -> 0 | W6: =IF(ISNUMBER(F6),ROUND(F6/'05_Assumptions'!$B$4,0),"") -> 2 | X6: =IF(AND(ISNUMBER(W6),ISNUMBER(J6)),MAX(0,W6-J6),"") -> 1 | Y6: =IF(NOT(ISNUMBER(J6)),"",IF(J6=0,"no RHU",IF(F6/J6>'05_Assumptions'!$B$4,"Yes","No"))) -> Yes | Z6: =IF(ISNUMBER(H6),H6,IF(AND(ISNUMBER(G6),ISNUMBER(I6)),G6-I6,"")) -> 5 | AA6: =IF(AND(ISNUMBER(G6),G6>0,ISNUMBER(Z6)),Z6/G6,"") -> 0.14705882 | AB6: =IF(AND(ISNUMBER(F6),F6>0,ISNUMBER(M6)),M6/F6*'05_Assumptions'!$B$6,"") | AC6: Barangay column preserves the 1,159-node 2020 model geography; current administrative coverage is 1,164 barangays and a five-barangay crosswalk is outstanding. 'Without a facility' = barangays with no matched registered health station. No bed column is carried in this annex. | AD6: =IF(ISNUMBER(F6),ROUNDUP(F6/'05_Assumptions'!$B$4,0),"") -> 3 | AE6: =IF(AND(ISNUMBER(AD6),ISNUMBER(J6)),MAX(0,AD6-J6),"") -> 2
A7: LDS | B7: Lanao del Sur | C7: Piagapo | D7: LGU | E7: LDS · ANNEX A · §A · p. 49 | F7: 40558 | G7: 37 | I7: 33 | J7: 1 | K7: 4 | L7: 0 | N7: 89.1 | O7: 65.7 | P7: 131.2 | Q7: 20.8 | R7: 2.2 | S7: 10.5 | T7: 40558 | U7: =IF(AND(ISNUMBER(J7),J7>0,ISNUMBER(F7)),F7/J7,"no RHU recorded") -> 40558 | V7: =IF(AND(ISNUMBER(T7),ISNUMBER(U7)),U7-T7,"") -> 0 | W7: =IF(ISNUMBER(F7),ROUND(F7/'05_Assumptions'!$B$4,0),"") -> 2 | X7: =IF(AND(ISNUMBER(W7),ISNUMBER(J7)),MAX(0,W7-J7),"") -> 1 | Y7: =IF(NOT(ISNUMBER(J7)),"",IF(J7=0,"no RHU",IF(F7/J7>'05_Assumptions'!$B$4,"Yes","No"))) -> Yes | Z7: =IF(ISNUMBER(H7),H7,IF(AND(ISNUMBER(G7),ISNUMBER(I7)),G7-I7,"")) -> 4 | AA7: =IF(AND(ISNUMBER(G7),G7>0,ISNUMBER(Z7)),Z7/G7,"") -> 0.10810811 | AB7: =IF(AND(ISNUMBER(F7),F7>0,ISNUMBER(M7)),M7/F7*'05_Assumptions'!$B$6,"") | AC7: Barangay column preserves the 1,159-node 2020 model geography; current administrative coverage is 1,164 barangays and a five-barangay crosswalk is outstanding. 'Without a facility' = barangays with no matched registered health station. No bed column is carried in this annex. | AD7: =IF(ISNUMBER(F7),ROUNDUP(F7/'05_Assumptions'!$B$4,0),"") -> 3 | AE7: =IF(AND(ISNUMBER(AD7),ISNUMBER(J7)),MAX(0,AD7-J7),"") -> 2
A8: LDS | B8: Lanao del Sur | C8: Balindong | D8: LGU | E8: LDS · ANNEX A · §A · p. 49 | F8: 40047 | G8: 38 | I8: 30 | J8: 1 | K8: 8 | L8: 1 | N8: 35.8 | O8: 85.1 | P8: 111.4 | Q8: 17.6 | R8: 0.2 | S8: 4.1 | T8: 40047 | U8: =IF(AND(ISNUMBER(J8),J8>0,ISNUMBER(F8)),F8/J8,"no RHU recorded") -> 40047 | V8: =IF(AND(ISNUMBER(T8),ISNUMBER(U8)),U8-T8,"") -> 0 | W8: =IF(ISNUMBER(F8),ROUND(F8/'05_Assumptions'!$B$4,0),"") -> 2 | X8: =IF(AND(ISNUMBER(W8),ISNUMBER(J8)),MAX(0,W8-J8),"") -> 1 | Y8: =IF(NOT(ISNUMBER(J8)),"",IF(J8=0,"no RHU",IF(F8/J8>'05_Assumptions'!$B$4,"Yes","No"))) -> Yes | Z8: =IF(ISNUMBER(H8),H8,IF(AND(ISNUMBER(G8),ISNUMBER(I8)),G8-I8,"")) -> 8 | AA8: =IF(AND(ISNUMBER(G8),G8>0,ISNUMBER(Z8)),Z8/G8,"") -> 0.21052632 | AB8: =IF(AND(ISNUMBER(F8),F8>0,ISNUMBER(M8)),M8/F8*'05_Assumptions'!$B$6,"") | AC8: Barangay column preserves the 1,159-node 2020 model geography; current administrative coverage is 1,164 barangays and a five-barangay crosswalk is outstanding. 'Without a facility' = barangays with no matched registered health station. No bed column is carried in this annex. | AD8: =IF(ISNUMBER(F8),ROUNDUP(F8/'05_Assumptions'!$B$4,0),"") -> 3 | AE8: =IF(AND(ISNUMBER(AD8),ISNUMBER(J8)),MAX(0,AD8-J8),"") -> 2
A9: LDS | B9: Lanao del Sur | C9: Maguing | D9: LGU | E9: LDS · ANNEX A · §A · p. 49 | F9: 37292 | G9: 34 | I9: 32 | J9: 1 | K9: 2 | L9: 0 | N9: 26.2 | O9: 83.8 | P9: 100.2 | Q9: 15.9 | R9: 1.3 | S9: 1.4 | T9: 37292 | U9: =IF(AND(ISNUMBER(J9),J9>0,ISNUMBER(F9)),F9/J9,"no RHU recorded") -> 37292 | V9: =IF(AND(ISNUMBER(T9),ISNUMBER(U9)),U9-T9,"") -> 0 | W9: =IF(ISNUMBER(F9),ROUND(F9/'05_Assumptions'!$B$4,0),"") -> 2 | X9: =IF(AND(ISNUMBER(W9),ISNUMBER(J9)),MAX(0,W9-J9),"") -> 1 | Y9: =IF(NOT(ISNUMBER(J9)),"",IF(J9=0,"no RHU",IF(F9/J9>'05_Assumptions'!$B$4,"Yes","No"))) -> Yes | Z9: =IF(ISNUMBER(H9),H9,IF(AND(ISNUMBER(G9),ISNUMBER(I9)),G9-I9,"")) -> 2 | AA9: =IF(AND(ISNUMBER(G9),G9>0,ISNUMBER(Z9)),Z9/G9,"") -> 0.058823529 | AB9: =IF(AND(ISNUMBER(F9),F9>0,ISNUMBER(M9)),M9/F9*'05_Assumptions'!$B$6,"") | AC9: Barangay column preserves the 1,159-node 2020 model geography; current administrative coverage is 1,164 barangays and a five-barangay crosswalk is outstanding. 'Without a facility' = barangays with no matched registered health station. No bed column is carried in this annex. | AD9: =IF(ISNUMBER(F9),ROUNDUP(F9/'05_Assumptions'!$B$4,0),"") -> 2 | AE9: =IF(AND(ISNUMBER(AD9),ISNUMBER(J9)),MAX(0,AD9-J9),"") -> 1
A10: LDS | B10: Lanao del Sur | C10: Tamparan | D10: LGU | E10: LDS · ANNEX A · §A · p. 49 | F10: 37190 | G10: 44 | I10: 44 | J10: 1 | K10: 0 | L10: 2 | N10: 98.4 | O10: 95.2 | P10: 139.2 | Q10: 22 | R10: 0.2 | S10: 0.6 | T10: 37190 | U10: =IF(AND(ISNUMBER(J10),J10>0,ISNUMBER(F10)),F10/J10,"no RHU recorded") -> 37190 | V10: =IF(AND(ISNUMBER(T10),ISNUMBER(U10)),U10-T10,"") -> 0 | W10: =IF(ISNUMBER(F10),ROUND(F10/'05_Assumptions'!$B$4,0),"") -> 2 | X10: =IF(AND(ISNUMBER(W10),ISNUMBER(J10)),MAX(0,W10-J10),"") -> 1 | Y10: =IF(NOT(ISNUMBER(J10)),"",IF(J10=0,"no RHU",IF(F10/J10>'05_Assumptions'!$B$4,"Yes","No"))) -> Yes | Z10: =IF(ISNUMBER(H10),H10,IF(AND(ISNUMBER(G10),ISNUMBER(I10)),G10-I10,"")) -> 0 | AA10: =IF(AND(ISNUMBER(G10),G10>0,ISNUMBER(Z10)),Z10/G10,"") -> 0 | AB10: =IF(AND(ISNUMBER(F10),F10>0,ISNUMBER(M10)),M10/F10*'05_Assumptions'!$B$6,"") | AC10: Barangay column preserves the 1,159-node 2020 model geography; current administrative coverage is 1,164 barangays and a five-barangay crosswalk is outstanding. 'Without a facility' = barangays with no matched registered health station. No bed column is carried in this annex. | AD10: =IF(ISNUMBER(F10),ROUNDUP(F10/'05_Assumptions'!$B$4,0),"") -> 2 | AE10: =IF(AND(ISNUMBER(AD10),ISNUMBER(J10)),MAX(0,AD10-J10),"") -> 1
A11: LDS | B11: Lanao del Sur | C11: Masiu | D11: LGU | E11: LDS · ANNEX A · §A · p. 49 | F11: 36803 | G11: 35 | I11: 32 | J11: 1 | K11: 3 | L11: 0 | N11: 101.4 | P11: 105.3 | Q11: 16.7 | R11: 2.5 | S11: 0.3 | T11: 36803 | U11: =IF(AND(ISNUMBER(J11),J11>0,ISNUMBER(F11)),F11/J11,"no RHU recorded") -> 36803 | V11: =IF(AND(ISNUMBER(T11),ISNUMBER(U11)),U11-T11,"") -> 0 | W11: =IF(ISNUMBER(F11),ROUND(F11/'05_Assumptions'!$B$4,0),"") -> 2 | X11: =IF(AND(ISNUMBER(W11),ISNUMBER(J11)),MAX(0,W11-J11),"") -> 1 | Y11: =IF(NOT(ISNUMBER(J11)),"",IF(J11=0,"no RHU",IF(F11/J11>'05_Assumptions'!$B$4,"Yes","No"))) -> Yes | Z11: =IF(ISNUMBER(H11),H11,IF(AND(ISNUMBER(G11),ISNUMBER(I11)),G11-I11,"")) -> 3 | AA11: =IF(AND(ISNUMBER(G11),G11>0,ISNUMBER(Z11)),Z11/G11,"") -> 0.085714286 | AB11: =IF(AND(ISNUMBER(F11),F11>0,ISNUMBER(M11)),M11/F11*'05_Assumptions'!$B$6,"") | AC11: Barangay column preserves the 1,159-node 2020 model geography; current administrative coverage is 1,164 barangays and a five-barangay crosswalk is outstanding. 'Without a facility' = barangays with no matched registered health station. No bed column is carried in this annex. | AD11: =IF(ISNUMBER(F11),ROUNDUP(F11/'05_Assumptions'!$B$4,0),"") -> 2 | AE11: =IF(AND(ISNUMBER(AD11),ISNUMBER(J11)),MAX(0,AD11-J11),"") -> 1
A12: LDS | B12: Lanao del Sur | C12: Ganassi | D12: LGU | E12: LDS · ANNEX A · §A · p. 49 | F12: 33897 | G12: 32 | I12: 32 | J12: 1 | K12: 0 | L12: 0 | N12: 6.6 | O12: 72 | P12: 72.5 | Q12: 11.5 | R12: 0.8 | S12: 5.1 | T12: 33897 | U12: =IF(AND(ISNUMBER(J12),J12>0,ISNUMBER(F12)),F12/J12,"no RHU recorded") -> 33897 | V12: =IF(AND(ISNUMBER(T12),ISNUMBER(U12)),U12-T12,"") -> 0 | W12: =IF(ISNUMBER(F12),ROUND(F12/'05_Assumptions'!$B$4,0),"") -> 2 | X12: =IF(AND(ISNUMBER(W12),ISNUMBER(J12)),MAX(0,W12-J12),"") -> 1 | Y12: =IF(NOT(ISNUMBER(J12)),"",IF(J12=0,"no RHU",IF(F12/J12>'05_Assumptions'!$B$4,"Yes","No"))) -> Yes | Z12: =IF(ISNUMBER(H12),H12,IF(AND(ISNUMBER(G12),ISNUMBER(I12)),G12-I12,"")) -> 0 | AA12: =IF(AND(ISNUMBER(G12),G12>0,ISNUMBER(Z12)),Z12/G12,"") -> 0 | AB12: =IF(AND(ISNUMBER(F12),F12>0,ISNUMBER(M12)),M12/F12*'05_Assumptions'!$B$6,"") | AC12: Barangay column preserves the 1,159-node 2020 model geography; current administrative coverage is 1,164 barangays and a five-barangay crosswalk is outstanding. 'Without a facility' = barangays with no matched registered health station. No bed column is carried in this annex. | AD12: =IF(ISNUMBER(F12),ROUNDUP(F12/'05_Assumptions'!$B$4,0),"") -> 2 | AE12: =IF(AND(ISNUMBER(AD12),ISNUMBER(J12)),MAX(0,AD12-J12),"") -> 1
A13: LDS | B13: Lanao del Sur | C13: Marogong | D13: LGU | E13: LDS · ANNEX A · §A · p. 49 | F13: 33595 | G13: 24 | I13: 19 | J13: 1 | K13: 5 | L13: 0 | N13: 81 | O13: 91.4 | P13: 222.4 | Q13: 35.2 | R13: 0.4 | S13: 0.9 | T13: 33595 | U13: =IF(AND(ISNUMBER(J13),J13>0,ISNUMBER(F13)),F13/J13,"no RHU recorded") -> 33595 | V13: =IF(AND(ISNUMBER(T13),ISNUMBER(U13)),U13-T13,"") -> 0 | W13: =IF(ISNUMBER(F13),ROUND(F13/'05_Assumptions'!$B$4,0),"") -> 2 | X13: =IF(AND(ISNUMBER(W13),ISNUMBER(J13)),MAX(0,W13-J13),"") -> 1 | Y13: =IF(NOT(ISNUMBER(J13)),"",IF(J13=0,"no RHU",IF(F13/J13>'05_Assumptions'!$B$4,"Yes","No"))) -> Yes | Z13: =IF(ISNUMBER(H13),H13,IF(AND(ISNUMBER(G13),ISNUMBER(I13)),G13-I13,"")) -> 5 | AA13: =IF(AND(ISNUMBER(G13),G13>0,ISNUMBER(Z13)),Z13/G13,"") -> 0.20833333 | AB13: =IF(AND(ISNUMBER(F13),F13>0,ISNUMBER(M13)),M13/F13*'05_Assumptions'!$B$6,"") | AC13: Barangay column preserves the 1,159-node 2020 model geography; current administrative coverage is 1,164 barangays and a five-barangay crosswalk is outstanding. 'Without a facility' = barangays with no matched registered health station. No bed column is carried in this annex. | AD13: =IF(ISNUMBER(F13),ROUNDUP(F13/'05_Assumptions'!$B$4,0),"") -> 2 | AE13: =IF(AND(ISNUMBER(AD13),ISNUMBER(J13)),MAX(0,AD13-J13),"") -> 1
A14: LDS | B14: Lanao del Sur | C14: Poona Bayabao | D14: LGU | E14: LDS · ANNEX A · §A · p. 49 | F14: 33307 | G14: 25 | I14: 23 | J14: 1 | K14: 2 | L14: 0 | N14: 39.9 | O14: 97 | P14: 110.6 | Q14: 17.5 | R14: 24.7 | S14: 1.1 | T14: 33307 | U14: =IF(AND(ISNUMBER(J14),J14>0,ISNUMBER(F14)),F14/J14,"no RHU recorded") -> 33307 | V14: =IF(AND(ISNUMBER(T14),ISNUMBER(U14)),U14-T14,"") -> 0 | W14: =IF(ISNUMBER(F14),ROUND(F14/'05_Assumptions'!$B$4,0),"") -> 2 | X14: =IF(AND(ISNUMBER(W14),ISNUMBER(J14)),MAX(0,W14-J14),"") -> 1 | Y14: =IF(NOT(ISNUMBER(J14)),"",IF(J14=0,"no RHU",IF(F14/J14>'05_Assumptions'!$B$4,"Yes","No"))) -> Yes | Z14: =IF(ISNUMBER(H14),H14,IF(AND(ISNUMBER(G14),ISNUMBER(I14)),G14-I14,"")) -> 2 | AA14: =IF(AND(ISNUMBER(G14),G14>0,ISNUMBER(Z14)),Z14/G14,"") -> 0.08 | AB14: =IF(AND(ISNUMBER(F14),F14>0,ISNUMBER(M14)),M14/F14*'05_Assumptions'!$B$6,"") | AC14: Barangay column preserves the 1,159-node 2020 model geography; current administrative coverage is 1,164 barangays and a five-barangay crosswalk is outstanding. 'Without a facility' = barangays with no matched registered health station. No bed column is carried in this annex. | AD14: =IF(ISNUMBER(F14),ROUNDUP(F14/'05_Assumptions'!$B$4,0),"") -> 2 | AE14: =IF(AND(ISNUMBER(AD14),ISNUMBER(J14)),MAX(0,AD14-J14),"") -> 1
A15: LDS | B15: Lanao del Sur | C15: Balabagan | D15: LGU | E15: LDS · ANNEX A · §A · p. 49 | F15: 31227 | G15: 27 | I15: 24 | J15: 1 | K15: 3 | L15: 0 | N15: 56.6 | O15: 96.1 | P15: 356.9 | Q15: 56.5 | R15: 1.2 | S15: 28.1 | T15: 31227 | U15: =IF(AND(ISNUMBER(J15),J15>0,ISNUMBER(F15)),F15/J15,"no RHU recorded") -> 31227 | V15: =IF(AND(ISNUMBER(T15),ISNUMBER(U15)),U15-T15,"") -> 0 | W15: =IF(ISNUMBER(F15),ROUND(F15/'05_Assumptions'!$B$4,0),"") -> 2 | X15: =IF(AND(ISNUMBER(W15),ISNUMBER(J15)),MAX(0,W15-J15),"") -> 1 | Y15: =IF(NOT(ISNUMBER(J15)),"",IF(J15=0,"no RHU",IF(F15/J15>'05_Assumptions'!$B$4,"Yes","No"))) -> Yes | Z15: =IF(ISNUMBER(H15),H15,IF(AND(ISNUMBER(G15),ISNUMBER(I15)),G15-I15,"")) -> 3 | AA15: =IF(AND(ISNUMBER(G15),G15>0,ISNUMBER(Z15)),Z15/G15,"") -> 0.11111111 | AB15: =IF(AND(ISNUMBER(F15),F15>0,ISNUMBER(M15)),M15/F15*'05_Assumptions'!$B$6,"") | AC15: Barangay column preserves the 1,159-node 2020 model geography; current administrative coverage is 1,164 barangays and a five-barangay crosswalk is outstanding. 'Without a facility' = barangays with no matched registered health station. No bed column is carried in this annex. | AD15: =IF(ISNUMBER(F15),ROUNDUP(F15/'05_Assumptions'!$B$4,0),"") -> 2 | AE15: =IF(AND(ISNUMBER(AD15),ISNUMBER(J15)),MAX(0,AD15-J15),"") -> 1
A16: LDS | B16: Lanao del Sur | C16: Bayang | D16: LGU | E16: LDS · ANNEX A · §A · p. 49 | F16: 30227 | G16: 49 | I16: 46 | J16: 1 | K16: 3 | L16: 0 | N16: 81 | O16: 0 | P16: 36.6 | Q16: 5.8 | R16: 2.2 | S16: 0.5 | T16: 30227 | U16: =IF(AND(ISNUMBER(J16),J16>0,ISNUMBER(F16)),F16/J16,"no RHU recorded") -> 30227 | V16: =IF(AND(ISNUMBER(T16),ISNUMBER(U16)),U16-T16,"") -> 0 | W16: =IF(ISNUMBER(F16),ROUND(F16/'05_Assumptions'!$B$4,0),"") -> 2 | X16: =IF(AND(ISNUMBER(W16),ISNUMBER(J16)),MAX(0,W16-J16),"") -> 1 | Y16: =IF(NOT(ISNUMBER(J16)),"",IF(J16=0,"no RHU",IF(F16/J16>'05_Assumptions'!$B$4,"Yes","No"))) -> Yes | Z16: =IF(ISNUMBER(H16),H16,IF(AND(ISNUMBER(G16),ISNUMBER(I16)),G16-I16,"")) -> 3 | AA16: =IF(AND(ISNUMBER(G16),G16>0,ISNUMBER(Z16)),Z16/G16,"") -> 0.06122449 | AB16: =IF(AND(ISNUMBER(F16),F16>0,ISNUMBER(M16)),M16/F16*'05_Assumptions'!$B$6,"") | AC16: Barangay column preserves the 1,159-node 2020 model geography; current administrative coverage is 1,164 barangays and a five-barangay crosswalk is outstanding. 'Without a facility' = barangays with no matched registered health station. No bed column is carried in this annex. | AD16: =IF(ISNUMBER(F16),ROUNDUP(F16/'05_Assumptions'!$B$4,0),"") -> 2 | AE16: =IF(AND(ISNUMBER(AD16),ISNUMBER(J16)),MAX(0,AD16-J16),"") -> 1
A17: LDS | B17: Lanao del Sur | C17: Madalum | D17: LGU | E17: LDS · ANNEX A · §A · p. 49 | F17: 30044 | G17: 37 | I17: 36 | J17: 1 | K17: 1 | L17: 0 | N17: 74.9 | P17: 72.2 | Q17: 11.4 | R17: 2.6 | S17: 0 | T17: 30044 | U17: =IF(AND(ISNUMBER(J17),J17>0,ISNUMBER(F17)),F17/J17,"no RHU recorded") -> 30044 | V17: =IF(AND(ISNUMBER(T17),ISNUMBER(U17)),U17-T17,"") -> 0 | W17: =IF(ISNUMBER(F17),ROUND(F17/'05_Assumptions'!$B$4,0),"") -> 2 | X17: =IF(AND(ISNUMBER(W17),ISNUMBER(J17)),MAX(0,W17-J17),"") -> 1 | Y17: =IF(NOT(ISNUMBER(J17)),"",IF(J17=0,"no RHU",IF(F17/J17>'05_Assumptions'!$B$4,"Yes","No"))) -> Yes | Z17: =IF(ISNUMBER(H17),H17,IF(AND(ISNUMBER(G17),ISNUMBER(I17)),G17-I17,"")) -> 1 | AA17: =IF(AND(ISNUMBER(G17),G17>0,ISNUMBER(Z17)),Z17/G17,"") -> 0.027027027 | AB17: =IF(AND(ISNUMBER(F17),F17>0,ISNUMBER(M17)),M17/F17*'05_Assumptions'!$B$6,"") | AC17: Barangay column preserves the 1,159-node 2020 model geography; current administrative coverage is 1,164 barangays and a five-barangay crosswalk is outstanding. 'Without a facility' = barangays with no matched registered health station. No bed column is carried in this annex. | AD17: =IF(ISNUMBER(F17),ROUNDUP(F17/'05_Assumptions'!$B$4,0),"") -> 2 | AE17: =IF(AND(ISNUMBER(AD17),ISNUMBER(J17)),MAX(0,AD17-J17),"") -> 1
